Workbook

Sheet Notes
A1: NOTES:
A2: 1 | B2: 8 hours = 1 day.
A3: 2 | B3: CL=Casual Leave; SL=Sick Leave; EL=Earned Leave.
A4: 3 | B4: If SL is applied, no half-day leave is allowed and only 50% salary will be given.
A5: 4 | B5: Dates must be in dd-mm-yyyy format.
A6: 5 | B6: Dates in the Columns "SL AVAILED" and "EL/VACATION UTILISED" are to be entered directly and not to be Cut/Copy from other Cells.
A7: 6 | B7: All Comp-offs must be authenticated by the respective Unit-heads and the Director.
A8: 7 | B8: 'Late C' means Late Coming; 'Early G' means Early Going and 'Gen.' means General.
A9: 8 | B9: In "Summary" Worksheet, under "BAL. OF COMP-OFF/LEAVES/LATE-EARLY C/f. TO NEXT MONTH", the Leaves which show NEGATIVE values, will become "0"(zero) in the next month.

Sheet Details
A1: PRINCESS ESIN WOMEN'S EDUCATIONAL CENTRE | AJ1: January | AK1: Confirmed
AJ2: February | AK2: Time-Scale
A3: Attendance and Leave details of the staff for the month of: | E3: January | F3: 2026 | AJ3: March | AK3: Contract
AJ4: April | AK4: Adhoc
A5: Details | AJ5: May | AK5: Part-time
AJ6: June
F7: CURRENT MONTH | O7: CURRENT MONTH | AA7: CURRENT MONTH | AJ7: July
H8: COMP-OFF GAINED | O8: CL AVAILED | R8: LATE CHECK-IN | U8: LATE C/EARLY G/GEN. PERMISSION | AA8: SL AVAILED | AD8: EL/VACATION CREDITED | AG8: EL/VACATION UTILISED | AJ8: August | AL8: BALANCE COMP-OFF/LEAVES/LATE C-EARLY G-GEN. PERM.
A9: Sl. | B9: Name of the Employee | C9: Designation | D9: Category | E9: Leave | F9: No. of | H9: Date | I9: No. of | J9: No. of | K9: Reason | L9: Converted into | O9: Date | P9: No. of | R9: Date | S9: No. of | U9: Date | V9: Late C/ | W9: No. of | X9: Converted into | AA9: Date | AB9: No. of | AD9: Date | AE9: No. of | AG9: Date | AH9: No. of | AJ9: September | AL9: AVAILABLE/ACCUMULATED TILL PREVIOUS MONTH
A10: No. | E10: System | F10: Days | I10: Days | J10: Hours | L10: Days | M10: Hours | P10: Days | S10: Days | V10: Early G/ | W10: Hours | X10: Days | Y10: Hours | AB10: Days | AE10: Days | AH10: Days | AJ10: October | AL10: Comp-Off | AO10: CL | AP10: SL | AQ10: EL/ | AS10: Late C/Early G/
E11: starts from | F11: Present | V11: Gen. | AJ11: November | AQ11: Vaca- | AS11: Gen. Perm.
E12: (Month) | V12: Perm. | AJ12: December | AL12: Days | AM12: Hours | AQ12: tion | AS12: Days | AT12: Hours
V13: (L/E/G)
A14: 1 | B14: D.B.N.V.J.Ramana | C14: Librarian | D14: Confirmed | E14: June | F14: =IF(C15="",DAY(EOMONTH(1&$E$3,0))-Summary!BC17,DAY(EOMONTH(1&$E$3,0))-Summary!BC17-(DAY(C15)-1)) -> 31 | H14: 46027 | J14: 2 | L14: =I38+IF(J38>=8,INT(J38/8),0) -> 0 | M14: =IF(J38>=8,J38-INT(J38/8)*8,J38) -> 2 | O14: 46041 | P14: 1 | S14: =COUNT(R14:R37) -> 0 | U14: 46034 | V14: L | W14: 1.5 | X14: =IF(W38>=8,INT(W38/8),0) -> 0 | Y14: =IF(X14>0,W38-X14*8,W38) -> 1.5 | AB14: =IF(COUNT(AA14:AA37)>AP14,"ERROR - Cannot avail more than SL balance",COUNT(AA14:AA37)) -> 0 | AL14: 0 | AM14: 0 | AO14: 0 | AP14: 12 | AQ14: 243 | AS14: 3.5
AD15: =IF($E$3="January",DATE($F$3,1,1),"") -> 46023 | AE15: =IF($E$3="January",15,"") -> 15
B16: =Summary!AT17 -> 0 | AD16: =IF($E$3="June",DATE($F$3,6,1),"") | AE16: =IF($E$3="June",15,"") | AG16: LOCK | AH16: LOCK
AD37: LOCK | AE37: LOCK | AG37: LOCK | AH37: LOCK
I38: =SUM(I14:I37) -> 0 | J38: =SUM(J14:J37) -> 2 | P38: =SUM(P14:P37) -> 1 | W38: =SUM(W14:W37) -> 1.5 | AE38: =SUM(AE14:AE37) -> 15 | AH38: =SUM(AH14:AH37) -> 0
A41: 2 | B41: V.C.S.S.V.Srinivasu | C41: A/cs. Supervisor | D41: Time-Scale | E41: January | F41: =IF(C42="",DAY(EOMONTH(1&$E$3,0))-Summary!BC18,DAY(EOMONTH(1&$E$3,0))-Summary!BC18-(DAY(C42)-1)) -> 31 | H41: 46024 | J41: 1 | L41: =I66+IF(J66>=8,INT(J66/8),0) -> 2 | M41: =IF(J66>=8,J66-INT(J66/8)*8,J66) -> 0.5 | S41: =COUNT(R41:R65) -> 0 | X41: =IF(W66>=8,INT(W66/8),0) -> 0 | Y41: =IF(X41>0,W66-X41*8,W66) -> 0 | AB41: =IF(COUNT(AA41:AA65)>AP41,"ERROR - Cannot avail more than SL balance",COUNT(AA41:AA65)) -> 0 | AL41: 48.5 | AM41: 5 | AO41: 12 | AP41: 15 | AQ41: 30 | AS41: 0 | AT41: 0
H42: 46030 | J42: 1 | AD42: =IF($E$3="January",DATE($F$3,1,1),"") -> 46023 | AE42: =IF($E$3="January",15,"") -> 15 | AG42: Input | AH42: Input
B43: =Summary!AT18 -> 50.5 | H43: 46031 | J43: 1 | AD43: =IF($E$3="June",DATE($F$3,6,1),"") | AE43: =IF($E$3="June",15,"") | AG43: LOCK | AH43: LOCK
H44: 46034 | J44: 1 | AD44: LOCK | AE44: LOCK | AG44: LOCK | AH44: LOCK
H45: 46035 | J45: 1
H46: 46038 | J46: 2
H47: 46042 | J47: 2.5
H48: 46043 | J48: 3
H49: 46041 | J49: 0.5
H50: 46049 | J50: 0.5
H51: 46051 | J51: 3
AD65: LOCK | AE65: LOCK | AG65: LOCK | AH65: LOCK
I66: =SUM(I41:I65) -> 0 | J66: =SUM(J41:J65) -> 16.5 | P66: =SUM(P41:P65) -> 0 | W66: =SUM(W41:W65) -> 0 | AE66: =SUM(AE41:AE65) -> 15 | AH66: =SUM(AH41:AH65) -> 0
A68: 3 | B68: Yadaiah | C68: Mali | D68: Confirmed | E68: June | F68: =IF(C69="",DAY(EOMONTH(1&$E$3,0))-Summary!BC19,DAY(EOMONTH(1&$E$3,0))-Summary!BC19-(DAY(C69)-1)) -> 31 | L68: =I93+IF(J93>=8,INT(J93/8),0) -> 0 | M68: =IF(J93>=8,J93-INT(J93/8)*8,J93) -> 0 | O68: 46030 | P68: 1 | S68: =COUNT(R68:R92) -> 0 | X68: =IF(W93>=8,INT(W93/8),0) -> 0 | Y68: =IF(X68>0,W93-X68*8,W93) -> 0 | AB68: =IF(COUNT(AA68:AA92)>AP68,"ERROR - Cannot avail more than SL balance",COUNT(AA68:AA92)) -> 0 | AL68: 0 | AM68: 3 | AO68: 0 | AP68: 15 | AQ68: 65 | AS68: 0 | AT68: 0
AD69: =IF($E$3="January",DATE($F$3,1,1),"") -> 46023 | AE69: =IF($E$3="January",8,"") -> 8 | AG69: Input | AH69: Input
B70: =Summary!AT19 -> 0 | AD70: =IF($E$3="June",DATE($F$3,6,1),"") | AE70: =IF($E$3="June",8,"") | AG70: LOCK | AH70: LOCK
AD71: LOCK | AE71: LOCK | AG71: LOCK | AH71: LOCK
AD92: LOCK | AE92: LOCK | AG92: LOCK | AH92: LOCK
I93: =SUM(I68:I92) -> 0 | J93: =SUM(J68:J92) -> 0 | P93: =SUM(P68:P92) -> 1 | W93: =SUM(W68:W92) -> 0 | AE93: =SUM(AE68:AE92) -> 8 | AH93: =SUM(AH68:AH92) -> 0
A95: 4 | B95: Syeda Jaweria Fatima | C95: Instructor | D95: Contract | E95: June | F95: =IF(C96="",DAY(EOMONTH(1&$E$3,0))-Summary!BC20,DAY(EOMONTH(1&$E$3,0))-Summary!BC20-(DAY(C96)-1)) -> 31 | H95: 46027 | J95: 1 | L95: =I120+IF(J120>=8,INT(J120/8),0) -> 0 | M95: =IF(J120>=8,J120-INT(J120/8)*8,J120) -> 1 | O95: 46034 | P95: 1 | S95: =COUNT(R95:R119) -> 0 | X95: =IF(W120>=8,INT(W120/8),0) -> 0 | Y95: =IF(X95>0,W120-X95*8,W120) -> 0 | AB95: =IF(COUNT(AA95:AA119)>AP95,"ERROR - Cannot avail more than SL balance",COUNT(AA95:AA119)) -> 0 | AD95: LOCK | AE95: LOCK | AL95: 0 | AM95: 3.5 | AO95: 0 | AP95: 8 | AQ95: 12 | AS95: 0 | AT95: 0
O96: 46038 | P96: 1 | AD96: =IF($E$3="June",DATE($F$3,12,1),"") | AE96: =IF($E$3="June",15,"")
B97: =Summary!AT20 -> 0 | AD97: LOCK | AE97: LOCK | AG97: LOCK | AH97: LOCK
...

Sheet Summary
A1: =Details!A1 -> PRINCESS ESIN WOMEN'S EDUCATIONAL CENTRE
A3: =Details!A3 -> Attendance and Leave details of the staff for the month of: | E3: =Details!E3 -> January | F3: =Details!F3 -> 2026
A5: Summary
F7: CURRENT MONTH | T7: LEAVES/COMP-OFF/LATE C-EARLY G-GEN. PERM. AVAILABLE | AD7: CURRENT MONTH'S COMP-OFF/LEAVES/LATE CHECK-IN/LATE C-EARLY G-GEN. PERM. ADJUSTED | AT7: BAL. COMP-OFF/LEAVES/LATE C-EARLY G-GEN. PERM. C/f. TO NEXT MONTH | BB7: STATUS
A8: Sl. | B8: Name of the Employee | C8: Designation | D8: Category | E8: Leave | F8: No. of | H8: Comp-off Gained | K8: CL | L8: Late | N8: Late C/ | Q8: SL | R8: EL/ | T8: Till Previous/ | X8: Till Current Month | AD8: Comp-off | AG8: CL | AL8: SL | AN8: EL/VACATION | AT8: Comp-off | AW8: CL | AX8: SL | AY8: EL/ | AZ8: Late C/ | BB8: LOP/FULL | BC8: If LOP,
A9: No. | E9: System | F9: Days | H9: Days | I9: Hours | K9: Availed | L9: Check- | N9: Early G/ | Q9: Availed | R9: Vaca- | T9: Current Month | X9: Comp-off | AA9: Late C/Early G/ | AD9: Days | AE9: Hours | AG9: CL | AH9: Late | AI9: Late C/ | AJ9: Total | AN9: CL | AO9: Late | AP9: Late C/ | AQ9: EL/ | AR9: Total | AT9: Days | AU9: Hours | AY9: Vaca- | AZ9: Early G/ | BC9: No. of
E10: starts from | F10: Present | L10: in | N10: Gen. Perm. | R10: tion | T10: CL | U10: SL | V10: EL/ | AA10: Gen. Perm. | AD10: (CL/Late C/ | AE10: (Late C/ | AH10: Check-in | AI10: Early G/ | AO10: Check-in | AP10: Early G/ | AQ10: Vaca- | AY10: tion | AZ10: Gen. Perm. | BC10: Days
E11: (Month) | N11: Days | O11: Hours | R11: Credi- | V11: Vaca- | X11: Days | Y11: Hours | AA11: Days | AB11: Hours | AD11: Early G/ | AE11: Early G/ | AI11: Gen. | AP11: Gen. | AQ11: tion | BC11: (includes
R12: ted | V12: tion | AD12: Gen. | AE12: Gen. | AI12: Perm. | AP12: Perm. | AQ12: Utili- | BC12: SL, if
AD13: Perm./ | AE13: Perm.) | AQ13: sed | BC13: availed)
AD14: SL)
K15: (in | L15: (in | Q15: (in | R15: (in | T15: (in | U15: (in | V15: (in | AG15: (in | AH15: (in | AI15: (in | AJ15: (in | AL15: (in | AN15: (in | AO15: (in | AP15: (in | AQ15: (in | AR15: (in | AW15: (in | AX15: (in | AY15: (in | AZ15: (in
K16: days) | L16: days) | Q16: days) | R16: days) | T16: days) | U16: days) | V16: days) | AG16: days) | AH16: days) | AI16: days) | AJ16: days) | AL16: days) | AN16: days) | AO16: days) | AP16: days) | AQ16: days) | AR16: days) | AW16: days) | AX16: days) | AY16: days) | AZ16: hours)
A17: =Details!A14 -> 1 | B17: =Details!B14 -> D.B.N.V.J.Ramana | C17: =Details!C14 -> Librarian | D17: =Details!D14 -> Confirmed | E17: =Details!E14 -> June | F17: =Details!F14 -> 31 | H17: =Details!L14 -> 0 | I17: =Details!M14 -> 2 | K17: =Details!P38 -> 1 | L17: =INT(Details!S14/3) -> 0 | N17: =Details!X14 -> 0 | O17: =Details!Y14 -> 1.5 | Q17: =Details!AB14 -> 0 | R17: =Details!AE38 -> 15 | T17: =IF(Details!$E$3="June",12,Details!AO14) -> 0 | U17: =IF(Details!$E$3="June",15,Details!AP14) -> 12 | V17: =Details!AQ14+Details!AE38 -> 258 | X17: =Details!AL14+Details!L14+IF(Details!AM14+Details!M14>=8,INT((Details!AM14+Details!M14)/8),0) -> 0 | Y17: =IF(Details!AM14+Details!M14>=8,Details!AM14+Details!M14-INT((Details!AM14+Details!M14)/8)*8,Details!AM14+Details!M14) -> 2 | AA17: =Details!AS14+Details!X14+IF(Details!AT14+Details!Y14>=8,INT((Details!AT14+Details!Y14)/8),0) -> 3.5 | AB17: =IF(Details!AT14+Details!Y14>=8,Details!AT14+Details!Y14-INT((Details!AT14+Details!Y14)/8)*8,Details!AT14+Details!Y14) -> 1.5 | AD17: =IF(X17<=K17,X17,K17+IF(X17-K17<=L17,X17-K17,L17+IF(X17-K17-L17<=AA17,X17-K17-L17,AA17+IF(X17-K17-L17-AA17<=Q17,X17-K17-L17-AA17,Q17)))) -> 0 | AE17: =IF(Y17<=AB17,Y17,AB17) -> 1.5 | AG17: =IF(V17=0,IF(K17>X17,K17-X17,0),IF(K17>X17,IF(T17<=(K17-X17),T17,K17-X17),0)) -> 0 | AH17: =IF(V17=0,IF(K17>=X17,L17,IF(X17-K17<L17,L17-(X17-K17),0)),IF(K17>=X17,IF(T17<=(K17-X17),0,IF(T17-(K17-X17)<=L17,T17-(K17-X17),L17)),IF(X17-K17<L17,IF(T17<=L17-(X17-K17),T17,L17-(X17-K17)),0))) -> 0 | AI17: =IF(V17=0,IF(K17>=X17,AA17,IF(X17-K17<L17,AA17,IF(X17-K17-L17<AA17,AA17-(X17-K17-L17),0))),IF(K17>=X17,IF(T17<=(K17-X17),0,IF(T17-(K17-X17)<=L17,0,IF(T17-(K17-(X17-L17))<=AA17,T17-(K17-(X17-L17)),AA17))),IF(X17-K17<L17,IF(T17<=L17-(X17-K17),0,IF(T17-(L17-(X17-K17))<=AA17,T17-(L17-(X17-K17)),AA17)),IF(X17-K17-L17<AA17,IF(T17<=L17-(X17-K17),0,IF(T17<=AA17-(X17-K17-L17),T17,AA17-(X17-K17-L17))),0)))) -> 0 | AJ17: =SUM(AG17:AI17) -> 0 | AL17: =IF(K17>=X17,Q17,IF(X17-K17<L17,Q17,IF(X17-K17-L17<AA17,Q17,IF(X17-K17-L17-AA17<Q17,Q17-(X17-K17-L17-AA17),0)))) -> 0 | AN17: =IF(V17>0,IF(K17>X17,IF(T17<=(K17-X17),K17-X17-T17,0),0),0) -> 1 | AO17: =IF(V17>0,IF(K17>=X17,IF(T17<=(K17-X17),L17,IF(T17-(K17-X17)<=L17,L17-(T17-(K17-X17)),0)),IF(T17<=L17-(X17-K17),L17-(X17-K17)-T17,0)),0) -> 0 | AP17: =IF(V17>0,IF(K17>=X17,IF(T17<=(K17-X17),AA17,IF(T17-(K17-X17)<=L17,AA17,IF(T17-(K17-(X17-L17))<=AA17,AA17-(T17-(K17-(X17-L17))),0))),IF(T17<=L17-(X17-K17),AA17,IF(T17-(L17-(X17-K17))<=AA17,AA17-(T17-(L17-(X17-K17))),0))),0) -> 3.5 | AQ17: =Details!AH38 -> 0 | AR17: =SUM(AN17:AQ17) -> 4.5 | AT17: =X17-AD17 -> 0 | AU17: =Y17-AE17 -> 0.5 | AW17: =T17-AJ17 -> 0 | AX17: =U17-AL17 -> 12 | AY17: =V17-AR17 -> 253.5 | AZ17: =IF(Y17<AB17,AB17-Y17,0) -> 0 | BB17: =IF(BC17>0,"LOP","FULL") -> FULL | BC17: =IF(AW17<0,ABS(AW17),0)+IF(AL17>0,AL17/2,0)+IF(AY17<0,ABS(AY17),0) -> 0
A18: =Details!A41 -> 2 | B18: =Details!B41 -> V.C.S.S.V.Srinivasu | C18: =Details!C41 -> A/cs. Supervisor | D18: =Details!D41 -> Time-Scale | E18: =Details!E41 -> January | F18: =Details!F41 -> 31 | H18: =Details!L41 -> 2 | I18: =Details!M41 -> 0.5 | K18: =Details!P66 -> 0 | L18: =INT(Details!S41/3) -> 0 | N18: =Details!X41 -> 0 | O18: =Details!Y41 -> 0 | Q18: =Details!AB41 -> 0 | R18: =Details!AE66 -> 15 | T18: =IF(Details!$E$3="January",12,Details!AO41) -> 12 | U18: =IF(Details!$E$3="January",15,Details!AP41) -> 15 | V18: =Details!AQ41+Details!AE66 -> 45 | X18: =Details!AL41+Details!L41+IF(Details!AM41+Details!M41>=8,INT((Details!AM41+Details!M41)/8),0) -> 50.5 | Y18: =IF(Details!AM41+Details!M41>=8,Details!AM41+Details!M41-INT((Details!AM41+Details!M41)/8)*8,Details!AM41+Details!M41) -> 5.5 | AA18: =Details!AS41+Details!X41+IF(Details!AT41+Details!Y41>=8,INT((Details!AT41+Details!Y41)/8),0) -> 0 | AB18: =IF(Details!AT41+Details!Y41>=8,Details!AT41+Details!Y41-INT((Details!AT41+Details!Y41)/8)*8,Details!AT41+Details!Y41) -> 0 | AD18: =IF(X18<=K18,X18,K18+IF(X18-K18<=L18,X18-K18,L18+IF(X18-K18-L18<=AA18,X18-K18-L18,AA18+IF(X18-K18-L18-AA18<=Q18,X18-K18-L18-AA18,Q18)))) -> 0 | AE18: =IF(Y18<=AB18,Y18,AB18) -> 0 | AG18: =IF(V18=0,IF(K18>X18,K18-X18,0),IF(K18>X18,IF(T18<=(K18-X18),T18,K18-X18),0)) -> 0 | AH18: =IF(V18=0,IF(K18>=X18,L18,IF(X18-K18<L18,L18-(X18-K18),0)),IF(K18>=X18,IF(T18<=(K18-X18),0,IF(T18-(K18-X18)<=L18,T18-(K18-X18),L18)),IF(X18-K18<L18,IF(T18<=L18-(X18-K18),T18,L18-(X18-K18)),0))) -> 0 | AI18: =IF(V18=0,IF(K18>=X18,AA18,IF(X18-K18<L18,AA18,IF(X18-K18-L18<AA18,AA18-(X18-K18-L18),0))),IF(K18>=X18,IF(T18<=(K18-X18),0,IF(T18-(K18-X18)<=L18,0,IF(T18-(K18-(X18-L18))<=AA18,T18-(K18-(X18-L18)),AA18))),IF(X18-K18<L18,IF(T18<=L18-(X18-K18),0,IF(T18-(L18-(X18-K18))<=AA18,T18-(L18-(X18-K18)),AA18)),IF(X18-K18-L18<AA18,IF(T18<=L18-(X18-K18),0,IF(T18<=AA18-(X18-K18-L18),T18,AA18-(X18-K18-L18))),0)))) -> 0 | AJ18: =SUM(AG18:AI18) -> 0 | AL18: =IF(K18>=X18,Q18,IF(X18-K18<L18,Q18,IF(X18-K18-L18<AA18,Q18,IF(X18-K18-L18-AA18<Q18,Q18-(X18-K18-L18-AA18),0)))) -> 0 | AN18: =IF(V18>0,IF(K18>X18,IF(T18<=(K18-X18),K18-X18-T18,0),0),0) -> 0 | AO18: =IF(V18>0,IF(K18>=X18,IF(T18<=(K18-X18),L18,IF(T18-(K18-X18)<=L18,L18-(T18-(K18-X18)),0)),IF(T18<=L18-(X18-K18),L18-(X18-K18)-T18,0)),0) -> 0 | AP18: =IF(V18>0,IF(K18>=X18,IF(T18<=(K18-X18),AA18,IF(T18-(K18-X18)<=L18,AA18,IF(T18-(K18-(X18-L18))<=AA18,AA18-(T18-(K18-(X18-L18))),0))),IF(T18<=L18-(X18-K18),AA18,IF(T18-(L18-(X18-K18))<=AA18,AA18-(T18-(L18-(X18-K18))),0))),0) -> 0 | AQ18: =Details!AH66 -> 0 | AR18: =SUM(AN18:AQ18) -> 0 | AT18: =X18-AD18 -> 50.5 | AU18: =Y18-AE18 -> 5.5 | AW18: =T18-AJ18 -> 12 | AX18: =U18-AL18 -> 15 | AY18: =V18-AR18 -> 45 | AZ18: =IF(Y18<AB18,AB18-Y18,0) -> 0 | BB18: =IF(BC18>0,"LOP","FULL") -> FULL | BC18: =IF(AW18<0,ABS(AW18),0)+IF(AL18>0,AL18/2,0)+IF(AY18<0,ABS(AY18),0) -> 0
A19: =Details!A68 -> 3 | B19: =Details!B68 -> Yadaiah | C19: =Details!C68 -> Mali | D19: =Details!D68 -> Confirmed | E19: =Details!E68 -> June | F19: =Details!F68 -> 31 | H19: =Details!L68 -> 0 | I19: =Details!M68 -> 0 | K19: =Details!P93 -> 1 | L19: =INT(Details!S68/3) -> 0 | N19: =Details!X68 -> 0 | O19: =Details!Y68 -> 0 | Q19: =Details!AB68 -> 0 | R19: =Details!AE93 -> 8 | T19: =IF(Details!$E$3="June",12,Details!AO68) -> 0 | U19: =IF(Details!$E$3="June",15,Details!AP68) -> 15 | V19: =Details!AQ68+Details!AE93 -> 73 | X19: =Details!AL68+Details!L68+IF(Details!AM68+Details!M68>=8,INT((Details!AM68+Details!M68)/8),0) -> 0 | Y19: =IF(Details!AM68+Details!M68>=8,Details!AM68+Details!M68-INT((Details!AM68+Details!M68)/8)*8,Details!AM68+Details!M68) -> 3 | AA19: =Details!AS68+Details!X68+IF(Details!AT68+Details!Y68>=8,INT((Details!AT68+Details!Y68)/8),0) -> 0 | AB19: =IF(Details!AT68+Details!Y68>=8,Details!AT68+Details!Y68-INT((Details!AT68+Details!Y68)/8)*8,Details!AT68+Details!Y68) -> 0 | AD19: =IF(X19<=K19,X19,K19+IF(X19-K19<=L19,X19-K19,L19+IF(X19-K19-L19<=AA19,X19-K19-L19,AA19+IF(X19-K19-L19-AA19<=Q19,X19-K19-L19-AA19,Q19)))) -> 0 | AE19: =IF(Y19<=AB19,Y19,AB19) -> 0 | AG19: =IF(V19=0,IF(K19>X19,K19-X19,0),IF(K19>X19,IF(T19<=(K19-X19),T19,K19-X19),0)) -> 0 | AH19: =IF(V19=0,IF(K19>=X19,L19,IF(X19-K19<L19,L19-(X19-K19),0)),IF(K19>=X19,IF(T19<=(K19-X19),0,IF(T19-(K19-X19)<=L19,T19-(K19-X19),L19)),IF(X19-K19<L19,IF(T19<=L19-(X19-K19),T19,L19-(X19-K19)),0))) -> 0 | AI19: =IF(V19=0,IF(K19>=X19,AA19,IF(X19-K19<L19,AA19,IF(X19-K19-L19<AA19,AA19-(X19-K19-L19),0))),IF(K19>=X19,IF(T19<=(K19-X19),0,IF(T19-(K19-X19)<=L19,0,IF(T19-(K19-(X19-L19))<=AA19,T19-(K19-(X19-L19)),AA19))),IF(X19-K19<L19,IF(T19<=L19-(X19-K19),0,IF(T19-(L19-(X19-K19))<=AA19,T19-(L19-(X19-K19)),AA19)),IF(X19-K19-L19<AA19,IF(T19<=L19-(X19-K19),0,IF(T19<=AA19-(X19-K19-L19),T19,AA19-(X19-K19-L19))),0)))) -> 0 | AJ19: =SUM(AG19:AI19) -> 0 | AL19: =IF(K19>=X19,Q19,IF(X19-K19<L19,Q19,IF(X19-K19-L19<AA19,Q19,IF(X19-K19-L19-AA19<Q19,Q19-(X19-K19-L19-AA19),0)))) -> 0 | AN19: =IF(V19>0,IF(K19>X19,IF(T19<=(K19-X19),K19-X19-T19,0),0),0) -> 1 | AO19: =IF(V19>0,IF(K19>=X19,IF(T19<=(K19-X19),L19,IF(T19-(K19-X19)<=L19,L19-(T19-(K19-X19)),0)),IF(T19<=L19-(X19-K19),L19-(X19-K19)-T19,0)),0) -> 0 | AP19: =IF(V19>0,IF(K19>=X19,IF(T19<=(K19-X19),AA19,IF(T19-(K19-X19)<=L19,AA19,IF(T19-(K19-(X19-L19))<=AA19,AA19-(T19-(K19-(X19-L19))),0))),IF(T19<=L19-(X19-K19),AA19,IF(T19-(L19-(X19-K19))<=AA19,AA19-(T19-(L19-(X19-K19))),0))),0) -> 0 | AQ19: =Details!AH93 -> 0 | AR19: =SUM(AN19:AQ19) -> 1 | AT19: =X19-AD19 -> 0 | AU19: =Y19-AE19 -> 3 | AW19: =T19-AJ19 -> 0 | AX19: =U19-AL19 -> 15 | AY19: =V19-AR19 -> 72 | AZ19: =IF(Y19<AB19,AB19-Y19,0) -> 0 | BB19: =IF(BC19>0,"LOP","FULL") -> FULL | BC19: =IF(AW19<0,ABS(AW19),0)+IF(AL19>0,AL19/2,0)+IF(AY19<0,ABS(AY19),0) -> 0
A20: =Details!A95 -> 4 | B20: =Details!B95 -> Syeda Jaweria Fatima | C20: =Details!C95 -> Instructor | D20: =Details!D95 -> Contract | E20: =Details!E95 -> June | F20: =Details!F95 -> 31 | H20: =Details!L95 -> 0 | I20: =Details!M95 -> 1 | K20: =Details!P120 -> 2 | L20: =INT(Details!S95/3) -> 0 | N20: =Details!X95 -> 0 | O20: =Details!Y95 -> 0 | Q20: =Details!AB95 -> 0 | R20: =Details!AE120 -> 0 | T20: =IF(Details!$E$3="June",12,Details!AO95) -> 0 | U20: =IF(Details!$E$3="June",8,Details!AP95) -> 8 | V20: =Details!AQ95+Details!AE120 -> 12 | X20: =Details!AL95+Details!L95+IF(Details!AM95+Details!M95>=8,INT((Details!AM95+Details!M95)/8),0) -> 0 | Y20: =IF(Details!AM95+Details!M95>=8,Details!AM95+Details!M95-INT((Details!AM95+Details!M95)/8)*8,Details!AM95+Details!M95) -> 4.5 | AA20: =Details!AS95+Details!X95+IF(Details!AT95+Details!Y95>=8,INT((Details!AT95+Details!Y95)/8),0) -> 0 | AB20: =IF(Details!AT95+Details!Y95>=8,Details!AT95+Details!Y95-INT((Details!AT95+Details!Y95)/8)*8,Details!AT95+Details!Y95) -> 0 | AD20: =IF(X20<=K20,X20,K20+IF(X20-K20<=L20,X20-K20,L20+IF(X20-K20-L20<=AA20,X20-K20-L20,AA20+IF(X20-K20-L20-AA20<=Q20,X20-K20-L20-AA20,Q20)))) -> 0 | AE20: =IF(Y20<=AB20,Y20,AB20) -> 0 | AG20: =IF(V20=0,IF(K20>X20,K20-X20,0),IF(K20>X20,IF(T20<=(K20-X20),T20,K20-X20),0)) -> 0 | AH20: =IF(V20=0,IF(K20>=X20,L20,IF(X20-K20<L20,L20-(X20-K20),0)),IF(K20>=X20,IF(T20<=(K20-X20),0,IF(T20-(K20-X20)<=L20,T20-(K20-X20),L20)),IF(X20-K20<L20,IF(T20<=L20-(X20-K20),T20,L20-(X20-K20)),0))) -> 0 | AI20: =IF(V20=0,IF(K20>=X20,AA20,IF(X20-K20<L20,AA20,IF(X20-K20-L20<AA20,AA20-(X20-K20-L20),0))),IF(K20>=X20,IF(T20<=(K20-X20),0,IF(T20-(K20-X20)<=L20,0,IF(T20-(K20-(X20-L20))<=AA20,T20-(K20-(X20-L20)),AA20))),IF(X20-K20<L20,IF(T20<=L20-(X20-K20),0,IF(T20-(L20-(X20-K20))<=AA20,T20-(L20-(X20-K20)),AA20)),IF(X20-K20-L20<AA20,IF(T20<=L20-(X20-K20),0,IF(T20<=AA20-(X20-K20-L20),T20,AA20-(X20-K20-L20))),0)))) -> 0 | AJ20: =SUM(AG20:AI20) -> 0 | AL20: =IF(K20>=X20,Q20,IF(X20-K20<L20,Q20,IF(X20-K20-L20<AA20,Q20,IF(X20-K20-L20-AA20<Q20,Q20-(X20-K20-L20-AA20),0)))) -> 0 | AN20: =IF(V20>0,IF(K20>X20,IF(T20<=(K20-X20),K20-X20-T20,0),0),0) -> 2 | AO20: =IF(V20>0,IF(K20>=X20,IF(T20<=(K20-X20),L20,IF(T20-(K20-X20)<=L20,L20-(T20-(K20-X20)),0)),IF(T20<=L20-(X20-K20),L20-(X20-K20)-T20,0)),0) -> 0 | AP20: =IF(V20>0,IF(K20>=X20,IF(T20<=(K20-X20),AA20,IF(T20-(K20-X20)<=L20,AA20,IF(T20-(K20-(X20-L20))<=AA20,AA20-(T20-(K20-(X20-L20))),0))),IF(T20<=L20-(X20-K20),AA20,IF(T20-(L20-(X20-K20))<=AA20,AA20-(T20-(L20-(X20-K20))),0))),0) -> 0 | AQ20: =Details!AH120 -> 0 | AR20: =SUM(AN20:AQ20) -> 2 | AT20: =X20-AD20 -> 0 | AU20: =Y20-AE20 -> 4.5 | AW20: =T20-AJ20 -> 0 | AX20: =U20-AL20 -> 8 | AY20: =V20-AR20 -> 10 | AZ20: =IF(Y20<AB20,AB20-Y20,0) -> 0 | BB20: =IF(BC20>0,"LOP","FULL") -> FULL | BC20: =IF(AW20<0,ABS(AW20),0)+IF(AL20>0,AL20/2,0)+IF(AY20<0,ABS(AY20),0) -> 0
A21: =Details!A122 -> 5 | B21: =Details!B122 -> G.Mahesh | C21: =Details!C122 -> Attender | D21: =Details!D122 -> Contract | E21: =Details!E122 -> November | F21: =Details!F122 -> 31 | H21: =Details!L122 -> 1 | I21: =Details!M122 -> 1 | K21: =Details!P147 -> 4 | L21: =INT(Details!S122/3) -> 0 | N21: =Details!X122 -> 0 | O21: =Details!Y122 -> 0 | Q21: =Details!AB122 -> 0 | R21: =Details!AE147 -> 0 | T21: =IF(Details!$E$3="November",12,Details!AO122) -> 12 | U21: =IF(Details!$E$3="November",8,Details!AP122) -> 8 | V21: =Details!AQ122+Details!AE147 -> 10 | X21: =Details!AL122+Details!L122+IF(Details!AM122+Details!M122>=8,INT((Details!AM122+Details!M122)/8),0) -> 7.5 | Y21: =IF(Details!AM122+Details!M122>=8,Details!AM122+Details!M122-INT((Details!AM122+Details!M122)/8)*8,Details!AM122+Details!M122) -> 7 | AA21: =Details!AS122+Details!X122+IF(Details!AT122+Details!Y122>=8,INT((Details!AT122+Details!Y122)/8),0) -> 0 | AB21: =IF(Details!AT122+Details!Y122>=8,Details!AT122+Details!Y122-INT((Details!AT122+Details!Y122)/8)*8,Details!AT122+Details!Y122) -> 0 | AD21: =IF(X21<=K21,X21,K21+IF(X21-K21<=L21,X21-K21,L21+IF(X21-K21-L21<=AA21,X21-K21-L21,AA21+IF(X21-K21-L21-AA21<=Q21,X21-K21-L21-AA21,Q21)))) -> 4 | AE21: =IF(Y21<=AB21,Y21,AB21) -> 0 | AG21: =IF(V21=0,IF(K21>X21,K21-X21,0),IF(K21>X21,IF(T21<=(K21-X21),T21,K21-X21),0)) -> 0 | AH21: =IF(V21=0,IF(K21>=X21,L21,IF(X21-K21<L21,L21-(X21-K21),0)),IF(K21>=X21,IF(T21<=(K21-X21),0,IF(T21-(K21-X21)<=L21,T21-(K21-X21),L21)),IF(X21-K21<L21,IF(T21<=L21-(X21-K21),T21,L21-(X21-K21)),0))) -> 0 | AI21: =IF(V21=0,IF(K21>=X21,AA21,IF(X21-K21<L21,AA21,IF(X21-K21-L21<AA21,AA21-(X21-K21-L21),0))),IF(K21>=X21,IF(T21<=(K21-X21),0,IF(T21-(K21-X21)<=L21,0,IF(T21-(K21-(X21-L21))<=AA21,T21-(K21-(X21-L21)),AA21))),IF(X21-K21<L21,IF(T21<=L21-(X21-K21),0,IF(T21-(L21-(X21-K21))<=AA21,T21-(L21-(X21-K21)),AA21)),IF(X21-K21-L21<AA21,IF(T21<=L21-(X21-K21),0,IF(T21<=AA21-(X21-K21-L21),T21,AA21-(X21-K21-L21))),0)))) -> 0 | AJ21: =SUM(AG21:AI21) -> 0 | AL21: =IF(K21>=X21,Q21,IF(X21-K21<L21,Q21,IF(X21-K21-L21<AA21,Q21,IF(X21-K21-L21-AA21<Q21,Q21-(X21-K21-L21-AA21),0)))) -> 0 | AN21: =IF(V21>0,IF(K21>X21,IF(T21<=(K21-X21),K21-X21-T21,0),0),0) -> 0 | AO21: =IF(V21>0,IF(K21>=X21,IF(T21<=(K21-X21),L21,IF(T21-(K21-X21)<=L21,L21-(T21-(K21-X21)),0)),IF(T21<=L21-(X21-K21),L21-(X21-K21)-T21,0)),0) -> 0 | AP21: =IF(V21>0,IF(K21>=X21,IF(T21<=(K21-X21),AA21,IF(T21-(K21-X21)<=L21,AA21,IF(T21-(K21-(X21-L21))<=AA21,AA21-(T21-(K21-(X21-L21))),0))),IF(T21<=L21-(X21-K21),AA21,IF(T21-(L21-(X21-K21))<=AA21,AA21-(T21-(L21-(X21-K21))),0))),0) -> 0 | AQ21: =Details!AH147 -> 0 | AR21: =SUM(AN21:AQ21) -> 0 | AT21: =X21-AD21 -> 3.5 | AU21: =Y21-AE21 -> 7 | AW21: =T21-AJ21 -> 12 | AX21: =U21-AL21 -> 8 | AY21: =V21-AR21 -> 10 | AZ21: =IF(Y21<AB21,AB21-Y21,0) -> 0 | BB21: =IF(BC21>0,"LOP","FULL") -> FULL | BC21: =IF(AW21<0,ABS(AW21),0)+IF(AL21>0,AL21/2,0)+IF(AY21<0,ABS(AY21),0) -> 0
A22: =Details!A149 -> 6 | B22: =Details!B149 -> S.Mosha | C22: =Details!C149 -> Officer Clerk | D22: =Details!D149 -> Adhoc | E22: =Details!E149 -> August | F22: =Details!F149 -> 31 | H22: =Details!L149 -> 0.5 | I22: =Details!M149 -> 4.5 | K22: =Details!P174 -> 2 | L22: =INT(Details!S149/3) -> 0 | N22: =Details!X149 -> 0 | O22: =Details!Y149 -> 0 | Q22: =Details!AB149 -> 0 | R22: =Details!AE174 -> 0 | T22: =Details!AO149 -> 6 | U22: =Details!AP149 -> 0 | V22: =Details!AQ149+Details!AE174 -> 0 | X22: =Details!AL149+Details!L149+IF(Details!AM149+Details!M149>=8,INT((Details!AM149+Details!M149)/8),0) -> 15.5 | Y22: =IF(Details!AM149+Details!M149>=8,Details!AM149+Details!M149-INT((Details!AM149+Details!M149)/8)*8,Details!AM149+Details!M149) -> 1.5 | AA22: =Details!AS149+Details!X149+IF(Details!AT149+Details!Y149>=8,INT((Details!AT149+Details!Y149)/8),0) -> 0 | AB22: =IF(Details!AT149+Details!Y149>=8,Details!AT149+Details!Y149-INT((Details!AT149+Details!Y149)/8)*8,Details!AT149+Details!Y149) -> 0 | AD22: =IF(X22<=K22,X22,K22+IF(X22-K22<=L22,X22-K22,L22+IF(X22-K22-L22<=AA22,X22-K22-L22,AA22+IF(X22-K22-L22-AA22<=Q22,X22-K22-L22-AA22,Q22)))) -> 2 | AE22: =IF(Y22<=AB22,Y22,AB22) -> 0 | AG22: =IF(V22=0,IF(K22>X22,K22-X22,0),IF(K22>X22,IF(T22<=(K22-X22),T22,K22-X22),0)) -> 0 | AH22: =IF(V22=0,IF(K22>=X22,L22,IF(X22-K22<L22,L22-(X22-K22),0)),IF(K22>=X22,IF(T22<=(K22-X22),0,IF(T22-(K22-X22)<=L22,T22-(K22-X22),L22)),IF(X22-K22<L22,IF(T22<=L22-(X22-K22),T22,L22-(X22-K22)),0))) -> 0 | AI22: =IF(V22=0,IF(K22>=X22,AA22,IF(X22-K22<L22,AA22,IF(X22-K22-L22<AA22,AA22-(X22-K22-L22),0))),IF(K22>=X22,IF(T22<=(K22-X22),0,IF(T22-(K22-X22)<=L22,0,IF(T22-(K22-(X22-L22))<=AA22,T22-(K22-(X22-L22)),AA22))),IF(X22-K22<L22,IF(T22<=L22-(X22-K22),0,IF(T22-(L22-(X22-K22))<=AA22,T22-(L22-(X22-K22)),AA22)),IF(X22-K22-L22<AA22,IF(T22<=L22-(X22-K22),0,IF(T22<=AA22-(X22-K22-L22),T22,AA22-(X22-K22-L22))),0)))) -> 0 | AJ22: =SUM(AG22:AI22) -> 0 | AL22: =IF(K22>=X22,Q22,IF(X22-K22<L22,Q22,IF(X22-K22-L22<AA22,Q22,IF(X22-K22-L22-AA22<Q22,Q22-(X22-K22-L22-AA22),0)))) -> 0 | AN22: =IF(V22>0,IF(K22>X22,IF(T22<=(K22-X22),K22-X22-T22,0),0),0) -> 0 | AO22: =IF(V22>0,IF(K22>=X22,IF(T22<=(K22-X22),L22,IF(T22-(K22-X22)<=L22,L22-(T22-(K22-X22)),0)),IF(T22<=L22-(X22-K22),L22-(X22-K22)-T22,0)),0) -> 0 | AP22: =IF(V22>0,IF(K22>=X22,IF(T22<=(K22-X22),AA22,IF(T22-(K22-X22)<=L22,AA22,IF(T22-(K22-(X22-L22))<=AA22,AA22-(T22-(K22-(X22-L22))),0))),IF(T22<=L22-(X22-K22),AA22,IF(T22-(L22-(X22-K22))<=AA22,AA22-(T22-(L22-(X22-K22))),0))),0) -> 0 | AQ22: =Details!AH174 -> 0 | AR22: =SUM(AN22:AQ22) -> 0 | AT22: =X22-AD22 -> 13.5 | AU22: =Y22-AE22 -> 1.5 | AW22: =T22-AJ22 -> 6 | AX22: =U22-AL22 -> 0 | AY22: =V22-AR22 -> 0 | AZ22: =IF(Y22<AB22,AB22-Y22,0) -> 0 | BB22: =IF(BC22>0,"LOP","FULL") -> FULL | BC22: =IF(AW22<0,ABS(AW22),0)+IF(AL22>0,AL22/2,0)+IF(AY22<0,ABS(AY22),0) -> 0
A23: =Details!A176 -> 7 | B23: =Details!B176 -> Vijaya Laxmi | C23: =Details!C176 -> Helper | D23: =Details!D176 -> Adhoc | E23: =Details!E176 -> July | F23: =Details!F176 -> 31 | H23: =Details!L176 -> 0 | I23: =Details!M176 -> 0 | K23: =Details!P201 -> 1 | L23: =INT(Details!S176/3) -> 0 | N23: =Details!X176 -> 0 | O23: =Details!Y176 -> 0 | Q23: =Details!AB176 -> 0 | R23: =Details!AE201 -> 0 | T23: =Details!AO176 -> 2.5 | U23: =Details!AP176 -> 0 | V23: =Details!AQ176+Details!AE201 -> 0 | X23: =Details!AL176+Details!L176+IF(Details!AM176+Details!M176>=8,INT((Details!AM176+Details!M176)/8),0) -> 0 | Y23: =IF(Details!AM176+Details!M176>=8,Details!AM176+Details!M176-INT((Details!AM176+Details!M176)/8)*8,Details!AM176+Details!M176) -> 0 | AA23: =Details!AS176+Details!X176+IF(Details!AT176+Details!Y176>=8,INT((Details!AT176+Details!Y176)/8),0) -> 0 | AB23: =IF(Details!AT176+Details!Y176>=8,Details!AT176+Details!Y176-INT((Details!AT176+Details!Y176)/8)*8,Details!AT176+Details!Y176) -> 0.5 | AD23: =IF(X23<=K23,X23,K23+IF(X23-K23<=L23,X23-K23,L23+IF(X23-K23-L23<=AA23,X23-K23-L23,AA23+IF(X23-K23-L23-AA23<=Q23,X23-K23-L23-AA23,Q23)))) -> 0 | AE23: =IF(Y23<=AB23,Y23,AB23) -> 0 | AG23: =IF(V23=0,IF(K23>X23,K23-X23,0),IF(K23>X23,IF(T23<=(K23-X23),T23,K23-X23),0)) -> 1 | AH23: =IF(V23=0,IF(K23>=X23,L23,IF(X23-K23<L23,L23-(X23-K23),0)),IF(K23>=X23,IF(T23<=(K23-X23),0,IF(T23-(K23-X23)<=L23,T23-(K23-X23),L23)),IF(X23-K23<L23,IF(T23<=L23-(X23-K23),T23,L23-(X23-K23)),0))) -> 0 | AI23: =IF(V23=0,IF(K23>=X23,AA23,IF(X23-K23<L23,AA23,IF(X23-K23-L23<AA23,AA23-(X23-K23-L23),0))),IF(K23>=X23,IF(T23<=(K23-X23),0,IF(T23-(K23-X23)<=L23,0,IF(T23-(K23-(X23-L23))<=AA23,T23-(K23-(X23-L23)),AA23))),IF(X23-K23<L23,IF(T23<=L23-(X23-K23),0,IF(T23-(L23-(X23-K23))<=AA23,T23-(L23-(X23-K23)),AA23)),IF(X23-K23-L23<AA23,IF(T23<=L23-(X23-K23),0,IF(T23<=AA23-(X23-K23-L23),T23,AA23-(X23-K23-L23))),0)))) -> 0 | AJ23: =SUM(AG23:AI23) -> 1 | AL23: =IF(K23>=X23,Q23,IF(X23-K23<L23,Q23,IF(X23-K23-L23<AA23,Q23,IF(X23-K23-L23-AA23<Q23,Q23-(X23-K23-L23-AA23),0)))) -> 0 | AN23: =IF(V23>0,IF(K23>X23,IF(T23<=(K23-X23),K23-X23-T23,0),0),0) -> 0 | AO23: =IF(V23>0,IF(K23>=X23,IF(T23<=(K23-X23),L23,IF(T23-(K23-X23)<=L23,L23-(T23-(K23-X23)),0)),IF(T23<=L23-(X23-K23),L23-(X23-K23)-T23,0)),0) -> 0 | AP23: =IF(V23>0,IF(K23>=X23,IF(T23<=(K23-X23),AA23,IF(T23-(K23-X23)<=L23,AA23,IF(T23-(K23-(X23-L23))<=AA23,AA23-(T23-(K23-(X23-L23))),0))),IF(T23<=L23-(X23-K23),AA23,IF(T23-(L23-(X23-K23))<=AA23,AA23-(T23-(L23-(X23-K23))),0))),0) -> 0 | AQ23: =Details!AH201 -> 0 | AR23: =SUM(AN23:AQ23) -> 0 | AT23: =X23-AD23 -> 0 | AU23: =Y23-AE23 -> 0 | AW23: =T23-AJ23 -> 1.5 | AX23: =U23-AL23 -> 0 | AY23: =V23-AR23 -> 0 | AZ23: =IF(Y23<AB23,AB23-Y23,0) -> 0.5 | BB23: =IF(BC23>0,"LOP","FULL") -> FULL | BC23: =IF(AW23<0,ABS(AW23),0)+IF(AL23>0,AL23/2,0)+IF(AY23<0,ABS(AY23),0) -> 0
A24: =Details!A203 -> 8 | B24: =Details!B203 -> S.B.Batool Naqvi | C24: =Details!C203 -> Instructor | D24: =Details!D203 -> Adhoc | E24: =Details!E203 -> November | F24: =Details!F203 -> 27 | H24: =Details!L203 -> 0 | I24: =Details!M203 -> 0 | K24: =Details!P228 -> 5 | L24: =INT(Details!S203/3) -> 0 | N24: =Details!X203 -> 0 | O24: =Details!Y203 -> 0 | Q24: =Details!AB203 -> 0 | R24: =Details!AE228 -> 0 | T24: =Details!AO203 -> 1 | U24: =Details!AP203 -> 0 | V24: =Details!AQ203+Details!AE228 -> 0 | X24: =Details!AL203+Details!L203+IF(Details!AM203+Details!M203>=8,INT((Details!AM203+Details!M203)/8),0) -> 0 | Y24: =IF(Details!AM203+Details!M203>=8,Details!AM203+Details!M203-INT((Details!AM203+Details!M203)/8)*8,Details!AM203+Details!M203) -> 3 | AA24: =Details!AS203+Details!X203+IF(Details!AT203+Details!Y203>=8,INT((Details!AT203+Details!Y203)/8),0) -> 0 | AB24: =IF(Details!AT203+Details!Y203>=8,Details!AT203+Details!Y203-INT((Details!AT203+Details!Y203)/8)*8,Details!AT203+Details!Y203) -> 0 | AD24: =IF(X24<=K24,X24,K24+IF(X24-K24<=L24,X24-K24,L24+IF(X24-K24-L24<=AA24,X24-K24-L24,AA24+IF(X24-K24-L24-AA24<=Q24,X24-K24-L24-AA24,Q24)))) -> 0 | AE24: =IF(Y24<=AB24,Y24,AB24) -> 0 | AG24: =IF(V24=0,IF(K24>X24,K24-X24,0),IF(K24>X24,IF(T24<=(K24-X24),T24,K24-X24),0)) -> 5 | AH24: =IF(V24=0,IF(K24>=X24,L24,IF(X24-K24<L24,L24-(X24-K24),0)),IF(K24>=X24,IF(T24<=(K24-X24),0,IF(T24-(K24-X24)<=L24,T24-(K24-X24),L24)),IF(X24-K24<L24,IF(T24<=L24-(X24-K24),T24,L24-(X24-K24)),0))) -> 0 | AI24: =IF(V24=0,IF(K24>=X24,AA24,IF(X24-K24<L24,AA24,IF(X24-K24-L24<AA24,AA24-(X24-K24-L24),0))),IF(K24>=X24,IF(T24<=(K24-X24),0,IF(T24-(K24-X24)<=L24,0,IF(T24-(K24-(X24-L24))<=AA24,T24-(K24-(X24-L24)),AA24))),IF(X24-K24<L24,IF(T24<=L24-(X24-K24),0,IF(T24-(L24-(X24-K24))<=AA24,T24-(L24-(X24-K24)),AA24)),IF(X24-K24-L24<AA24,IF(T24<=L24-(X24-K24),0,IF(T24<=AA24-(X24-K24-L24),T24,AA24-(X24-K24-L24))),0)))) -> 0 | AJ24: =SUM(AG24:AI24) -> 5 | AL24: =IF(K24>=X24,Q24,IF(X24-K24<L24,Q24,IF(X24-K24-L24<AA24,Q24,IF(X24-K24-L24-AA24<Q24,Q24-(X24-K24-L24-AA24),0)))) -> 0 | AN24: =IF(V24>0,IF(K24>X24,IF(T24<=(K24-X24),K24-X24-T24,0),0),0) -> 0 | AO24: =IF(V24>0,IF(K24>=X24,IF(T24<=(K24-X24),L24,IF(T24-(K24-X24)<=L24,L24-(T24-(K24-X24)),0)),IF(T24<=L24-(X24-K24),L24-(X24-K24)-T24,0)),0) -> 0 | AP24: =IF(V24>0,IF(K24>=X24,IF(T24<=(K24-X24),AA24,IF(T24-(K24-X24)<=L24,AA24,IF(T24-(K24-(X24-L24))<=AA24,AA24-(T24-(K24-(X24-L24))),0))),IF(T24<=L24-(X24-K24),AA24,IF(T24-(L24-(X24-K24))<=AA24,AA24-(T24-(L24-(X24-K24))),0))),0) -> 0 | AQ24: =Details!AH228 -> 0 | AR24: =SUM(AN24:AQ24) -> 0 | AT24: =X24-AD24 -> 0 | AU24: =Y24-AE24 -> 3 | AW24: =T24-AJ24 -> -4 | AX24: =U24-AL24 -> 0 | AY24: =V24-AR24 -> 0 | AZ24: =IF(Y24<AB24,AB24-Y24,0) -> 0 | BB24: =IF(BC24>0,"LOP","FULL") -> LOP | BC24: =IF(AW24<0,ABS(AW24),0)+IF(AL24>0,AL24/2,0)+IF(AY24<0,ABS(AY24),0) -> 4
A25: =Details!A230 -> 9 | B25: =Details!B230 -> Hajera Fatima | C25: =Details!C230 -> Accountant | D25: =Details!D230 -> Adhoc | E25: =Details!E230 -> May | F25: =Details!F230 -> 31 | H25: =Details!L230 -> 0.5 | I25: =Details!M230 -> 1 | K25: =Details!P255 -> 0 | L25: =INT(Details!S230/3) -> 0 | N25: =Details!X230 -> 0 | O25: =Details!Y230 -> 0 | Q25: =Details!AB230 -> 0 | R25: =Details!AE255 -> 0 | T25: =Details!AO230 -> 9 | U25: =Details!AP230 -> 0 | V25: =Details!AQ230+Details!AE255 -> 0 | X25: =Details!AL230+Details!L230+IF(Details!AM230+Details!M230>=8,INT((Details!AM230+Details!M230)/8),0) -> 5.5 | Y25: =IF(Details!AM230+Details!M230>=8,Details!AM230+Details!M230-INT((Details!AM230+Details!M230)/8)*8,Details!AM230+Details!M230) -> 7.5 | AA25: =Details!AS230+Details!X230+IF(Details!AT230+Details!Y230>=8,INT((Details!AT230+Details!Y230)/8),0) -> 0 | AB25: =IF(Details!AT230+Details!Y230>=8,Details!AT230+Details!Y230-INT((Details!AT230+Details!Y230)/8)*8,Details!AT230+Details!Y230) -> 0 | AD25: =IF(X25<=K25,X25,K25+IF(X25-K25<=L25,X25-K25,L25+IF(X25-K25-L25<=AA25,X25-K25-L25,AA25+IF(X25-K25-L25-AA25<=Q25,X25-K25-L25-AA25,Q25)))) -> 0 | AE25: =IF(Y25<=AB25,Y25,AB25) -> 0 | AG25: =IF(V25=0,IF(K25>X25,K25-X25,0),IF(K25>X25,IF(T25<=(K25-X25),T25,K25-X25),0)) -> 0 | AH25: =IF(V25=0,IF(K25>=X25,L25,IF(X25-K25<L25,L25-(X25-K25),0)),IF(K25>=X25,IF(T25<=(K25-X25),0,IF(T25-(K25-X25)<=L25,T25-(K25-X25),L25)),IF(X25-K25<L25,IF(T25<=L25-(X25-K25),T25,L25-(X25-K25)),0))) -> 0 | AI25: =IF(V25=0,IF(K25>=X25,AA25,IF(X25-K25<L25,AA25,IF(X25-K25-L25<AA25,AA25-(X25-K25-L25),0))),IF(K25>=X25,IF(T25<=(K25-X25),0,IF(T25-(K25-X25)<=L25,0,IF(T25-(K25-(X25-L25))<=AA25,T25-(K25-(X25-L25)),AA25))),IF(X25-K25<L25,IF(T25<=L25-(X25-K25),0,IF(T25-(L25-(X25-K25))<=AA25,T25-(L25-(X25-K25)),AA25)),IF(X25-K25-L25<AA25,IF(T25<=L25-(X25-K25),0,IF(T25<=AA25-(X25-K25-L25),T25,AA25-(X25-K25-L25))),0)))) -> 0 | AJ25: =SUM(AG25:AI25) -> 0 | AL25: =IF(K25>=X25,Q25,IF(X25-K25<L25,Q25,IF(X25-K25-L25<AA25,Q25,IF(X25-K25-L25-AA25<Q25,Q25-(X25-K25-L25-AA25),0)))) -> 0 | AN25: =IF(V25>0,IF(K25>X25,IF(T25<=(K25-X25),K25-X25-T25,0),0),0) -> 0 | AO25: =IF(V25>0,IF(K25>=X25,IF(T25<=(K25-X25),L25,IF(T25-(K25-X25)<=L25,L25-(T25-(K25-X25)),0)),IF(T25<=L25-(X25-K25),L25-(X25-K25)-T25,0)),0) -> 0 | AP25: =IF(V25>0,IF(K25>=X25,IF(T25<=(K25-X25),AA25,IF(T25-(K25-X25)<=L25,AA25,IF(T25-(K25-(X25-L25))<=AA25,AA25-(T25-(K25-(X25-L25))),0))),IF(T25<=L25-(X25-K25),AA25,IF(T25-(L25-(X25-K25))<=AA25,AA25-(T25-(L25-(X25-K25))),0))),0) -> 0 | AQ25: =Details!AH255 -> 0 | AR25: =SUM(AN25:AQ25) -> 0 | AT25: =X25-AD25 -> 5.5 | AU25: =Y25-AE25 -> 7.5 | AW25: =T25-AJ25 -> 9 | AX25: =U25-AL25 -> 0 | AY25: =V25-AR25 -> 0 | AZ25: =IF(Y25<AB25,AB25-Y25,0) -> 0 | BB25: =IF(BC25>0,"LOP","FULL") -> FULL | BC25: =IF(AW25<0,ABS(AW25),0)+IF(AL25>0,AL25/2,0)+IF(AY25<0,ABS(AY25),0) -> 0
A26: =Details!A257 -> 10 | B26: =Details!B257 -> C. Subha Venugopal | C26: =Details!C257 -> Instructor | D26: =Details!D257 -> Adhoc | E26: =Details!E257 -> May | F26: =Details!F257 -> 31 | H26: =Details!L257 -> 0 | I26: =Details!M257 -> 0 | K26: =Details!P282 -> 1 | L26: =INT(Details!S257/3) -> 0 | N26: =Details!X257 -> 0 | O26: =Details!Y257 -> 0 | Q26: =Details!AB257 -> 0 | R26: =Details!AE282 -> 0 | T26: =Details!AO257 -> 2 | U26: =Details!AP257 -> 0 | V26: =Details!AQ257+Details!AE282 -> 0 | X26: =Details!AL257+Details!L257+IF(Details!AM257+Details!M257>=8,INT((Details!AM257+Details!M257)/8),0) -> 0 | Y26: =IF(Details!AM257+Details!M257>=8,Details!AM257+Details!M257-INT((Details!AM257+Details!M257)/8)*8,Details!AM257+Details!M257) -> 3 | AA26: =Details!AS257+Details!X257+IF(Details!AT257+Details!Y257>=8,INT((Details!AT257+Details!Y257)/8),0) -> 0 | AB26: =IF(Details!AT257+Details!Y257>=8,Details!AT257+Details!Y257-INT((Details!AT257+Details!Y257)/8)*8,Details!AT257+Details!Y257) -> 0 | AD26: =IF(X26<=K26,X26,K26+IF(X26-K26<=L26,X26-K26,L26+IF(X26-K26-L26<=AA26,X26-K26-L26,AA26+IF(X26-K26-L26-AA26<=Q26,X26-K26-L26-AA26,Q26)))) -> 0 | AE26: =IF(Y26<=AB26,Y26,AB26) -> 0 | AG26: =IF(V26=0,IF(K26>X26,K26-X26,0),IF(K26>X26,IF(T26<=(K26-X26),T26,K26-X26),0)) -> 1 | AH26: =IF(V26=0,IF(K26>=X26,L26,IF(X26-K26<L26,L26-(X26-K26),0)),IF(K26>=X26,IF(T26<=(K26-X26),0,IF(T26-(K26-X26)<=L26,T26-(K26-X26),L26)),IF(X26-K26<L26,IF(T26<=L26-(X26-K26),T26,L26-(X26-K26)),0))) -> 0 | AI26: =IF(V26=0,IF(K26>=X26,AA26,IF(X26-K26<L26,AA26,IF(X26-K26-L26<AA26,AA26-(X26-K26-L26),0))),IF(K26>=X26,IF(T26<=(K26-X26),0,IF(T26-(K26-X26)<=L26,0,IF(T26-(K26-(X26-L26))<=AA26,T26-(K26-(X26-L26)),AA26))),IF(X26-K26<L26,IF(T26<=L26-(X26-K26),0,IF(T26-(L26-(X26-K26))<=AA26,T26-(L26-(X26-K26)),AA26)),IF(X26-K26-L26<AA26,IF(T26<=L26-(X26-K26),0,IF(T26<=AA26-(X26-K26-L26),T26,AA26-(X26-K26-L26))),0)))) -> 0 | AJ26: =SUM(AG26:AI26) -> 1 | AL26: =IF(K26>=X26,Q26,IF(X26-K26<L26,Q26,IF(X26-K26-L26<AA26,Q26,IF(X26-K26-L26-AA26<Q26,Q26-(X26-K26-L26-AA26),0)))) -> 0 | AN26: =IF(V26>0,IF(K26>X26,IF(T26<=(K26-X26),K26-X26-T26,0),0),0) -> 0 | AO26: =IF(V26>0,IF(K26>=X26,IF(T26<=(K26-X26),L26,IF(T26-(K26-X26)<=L26,L26-(T26-(K26-X26)),0)),IF(T26<=L26-(X26-K26),L26-(X26-K26)-T26,0)),0) -> 0 | AP26: =IF(V26>0,IF(K26>=X26,IF(T26<=(K26-X26),AA26,IF(T26-(K26-X26)<=L26,AA26,IF(T26-(K26-(X26-L26))<=AA26,AA26-(T26-(K26-(X26-L26))),0))),IF(T26<=L26-(X26-K26),AA26,IF(T26-(L26-(X26-K26))<=AA26,AA26-(T26-(L26-(X26-K26))),0))),0) -> 0 | AQ26: =Details!AH282 -> 0 | AR26: =SUM(AN26:AQ26) -> 0 | AT26: =X26-AD26 -> 0 | AU26: =Y26-AE26 -> 3 | AW26: =T26-AJ26 -> 1 | AX26: =U26-AL26 -> 0 | AY26: =V26-AR26 -> 0 | AZ26: =IF(Y26<AB26,AB26-Y26,0) -> 0 | BB26: =IF(BC26>0,"LOP","FULL") -> FULL | BC26: =IF(AW26<0,ABS(AW26),0)+IF(AL26>0,AL26/2,0)+IF(AY26<0,ABS(AY26),0) -> 0
A27: =Details!A284 -> 11 | B27: =Details!B284 -> Samreen Begum | C27: =Details!C284 -> Instructor | D27: =Details!D284 -> Adhoc | E27: =Details!E284 -> July | F27: =Details!F284 -> 31 | H27: =Details!L284 -> 0.5 | I27: =Details!M284 -> 0 | K27: =Details!P309 -> 0 | L27: =INT(Details!S284/3) -> 0 | N27: =Details!X284 -> 0 | O27: =Details!Y284 -> 0 | Q27: =Details!AB284 -> 0 | R27: =Details!AE309 -> 0 | T27: =Details!AO284 -> 1.5 | U27: =Details!AP284 -> 0 | V27: =Details!AQ284+Details!AE309 -> 0 | X27: =Details!AL284+Details!L284+IF(Details!AM284+Details!M284>=8,INT((Details!AM284+Details!M284)/8),0) -> 0.5 | Y27: =IF(Details!AM284+Details!M284>=8,Details!AM284+Details!M284-INT((Details!AM284+Details!M284)/8)*8,Details!AM284+Details!M284) -> 2 | AA27: =Details!AS284+Details!X284+IF(Details!AT284+Details!Y284>=8,INT((Details!AT284+Details!Y284)/8),0) -> 0 | AB27: =IF(Details!AT284+Details!Y284>=8,Details!AT284+Details!Y284-INT((Details!AT284+Details!Y284)/8)*8,Details!AT284+Details!Y284) -> 0 | AD27: =IF(X27<=K27,X27,K27+IF(X27-K27<=L27,X27-K27,L27+IF(X27-K27-L27<=AA27,X27-K27-L27,AA27+IF(X27-K27-L27-AA27<=Q27,X27-K27-L27-AA27,Q27)))) -> 0 | AE27: =IF(Y27<=AB27,Y27,AB27) -> 0 | AG27: =IF(V27=0,IF(K27>X27,K27-X27,0),IF(K27>X27,IF(T27<=(K27-X27),T27,K27-X27),0)) -> 0 | AH27: =IF(V27=0,IF(K27>=X27,L27,IF(X27-K27<L27,L27-(X27-K27),0)),IF(K27>=X27,IF(T27<=(K27-X27),0,IF(T27-(K27-X27)<=L27,T27-(K27-X27),L27)),IF(X27-K27<L27,IF(T27<=L27-(X27-K27),T27,L27-(X27-K27)),0))) -> 0 | AI27: =IF(V27=0,IF(K27>=X27,AA27,IF(X27-K27<L27,AA27,IF(X27-K27-L27<AA27,AA27-(X27-K27-L27),0))),IF(K27>=X27,IF(T27<=(K27-X27),0,IF(T27-(K27-X27)<=L27,0,IF(T27-(K27-(X27-L27))<=AA27,T27-(K27-(X27-L27)),AA27))),IF(X27-K27<L27,IF(T27<=L27-(X27-K27),0,IF(T27-(L27-(X27-K27))<=AA27,T27-(L27-(X27-K27)),AA27)),IF(X27-K27-L27<AA27,IF(T27<=L27-(X27-K27),0,IF(T27<=AA27-(X27-K27-L27),T27,AA27-(X27-K27-L27))),0)))) -> 0 | AJ27: =SUM(AG27:AI27) -> 0 | AL27: =IF(K27>=X27,Q27,IF(X27-K27<L27,Q27,IF(X27-K27-L27<AA27,Q27,IF(X27-K27-L27-AA27<Q27,Q27-(X27-K27-L27-AA27),0)))) -> 0 | AN27: =IF(V27>0,IF(K27>X27,IF(T27<=(K27-X27),K27-X27-T27,0),0),0) -> 0 | AO27: =IF(V27>0,IF(K27>=X27,IF(T27<=(K27-X27),L27,IF(T27-(K27-X27)<=L27,L27-(T27-(K27-X27)),0)),IF(T27<=L27-(X27-K27),L27-(X27-K27)-T27,0)),0) -> 0 | AP27: =IF(V27>0,IF(K27>=X27,IF(T27<=(K27-X27),AA27,IF(T27-(K27-X27)<=L27,AA27,IF(T27-(K27-(X27-L27))<=AA27,AA27-(T27-(K27-(X27-L27))),0))),IF(T27<=L27-(X27-K27),AA27,IF(T27-(L27-(X27-K27))<=AA27,AA27-(T27-(L27-(X27-K27))),0))),0) -> 0 | AQ27: =Details!AH309 -> 0 | AR27: =SUM(AN27:AQ27) -> 0 | AT27: =X27-AD27 -> 0.5 | AU27: =Y27-AE27 -> 2 | AW27: =T27-AJ27 -> 1.5 | AX27: =U27-AL27 -> 0 | AY27: =V27-AR27 -> 0 | AZ27: =IF(Y27<AB27,AB27-Y27,0) -> 0 | BB27: =IF(BC27>0,"LOP","FULL") -> FULL | BC27: =IF(AW27<0,ABS(AW27),0)+IF(AL27>0,AL27/2,0)+IF(AY27<0,ABS(AY27),0) -> 0
A32: =Details!A314 -> DIRECTOR | C32: =Details!C314 -> ACCOUNTS MANAGER
A34: =Details!A316 -> Date: 30-01-2026 | C34: =Details!C316 -> ACCOUNTANT
C36: =Details!C318 -> OFFICE SECRETARY/CLERK
